Internal Server Error: /api/news/update
Traceback (most recent call last):
  File "/home/apollo/.local/lib/python3.10/site-packages/django/db/backends/base/base.py", line 275, in ensure_connection
    self.connect()
  File "/home/apollo/.local/lib/python3.10/site-packages/django/utils/asyncio.py", line 26, in inner
    return func(*args, **kwargs)
  File "/home/apollo/.local/lib/python3.10/site-packages/django/db/backends/base/base.py", line 256, in connect
    self.connection = self.get_new_connection(conn_params)
  File "/home/apollo/.local/lib/python3.10/site-packages/django/utils/asyncio.py", line 26, in inner
    return func(*args, **kwargs)
  File "/home/apollo/.local/lib/python3.10/site-packages/django/db/backends/postgresql/base.py", line 277, in get_new_connection
    connection = self.Database.connect(**conn_params)
  File "/home/apollo/.local/lib/python3.10/site-packages/psycopg2/__init__.py", line 122, in connect
    conn = _connect(dsn, connection_factory=connection_factory, **kwasync)
psycopg2.OperationalError: connection to server on socket "/var/run/postgresql/.s.PGSQL.5432" failed: No such file or directory
	Is the server running locally and accepting connections on that socket?


The above exception was the direct cause of the following exception:

Traceback (most recent call last):
  File "/home/apollo/.local/lib/python3.10/site-packages/django/core/handlers/exception.py", line 55, in inner
    response = get_response(request)
  File "/home/apollo/.local/lib/python3.10/site-packages/django/core/handlers/base.py", line 197, in _get_response
    response = wrapped_callback(request, *callback_args, **callback_kwargs)
  File "/home/apollo/.local/lib/python3.10/site-packages/django/views/decorators/csrf.py", line 65, in _view_wrapper
    return view_func(request, *args, **kwargs)
  File "/home/apollo/.local/lib/python3.10/site-packages/rest_framework/viewsets.py", line 124, in view
    return self.dispatch(request, *args, **kwargs)
  File "/home/apollo/.local/lib/python3.10/site-packages/rest_framework/views.py", line 509, in dispatch
    response = self.handle_exception(exc)
  File "/home/apollo/.local/lib/python3.10/site-packages/rest_framework/views.py", line 469, in handle_exception
    self.raise_uncaught_exception(exc)
  File "/home/apollo/.local/lib/python3.10/site-packages/rest_framework/views.py", line 480, in raise_uncaught_exception
    raise exc
  File "/home/apollo/.local/lib/python3.10/site-packages/rest_framework/views.py", line 506, in dispatch
    response = handler(request, *args, **kwargs)
  File "/mnt/c/Users/pythonCode/django/porfolio/src/news/views.py", line 82, in update
    news = News.objects.first()
  File "/home/apollo/.local/lib/python3.10/site-packages/django/db/models/manager.py", line 87, in manager_method
    return getattr(self.get_queryset(), name)(*args, **kwargs)
  File "/home/apollo/.local/lib/python3.10/site-packages/django/db/models/query.py", line 1097, in first
    for obj in queryset[:1]:
  File "/home/apollo/.local/lib/python3.10/site-packages/django/db/models/query.py", line 400, in __iter__
    self._fetch_all()
  File "/home/apollo/.local/lib/python3.10/site-packages/django/db/models/query.py", line 1928, in _fetch_all
    self._result_cache = list(self._iterable_class(self))
  File "/home/apollo/.local/lib/python3.10/site-packages/django/db/models/query.py", line 91, in __iter__
    results = compiler.execute_sql(
  File "/home/apollo/.local/lib/python3.10/site-packages/django/db/models/sql/compiler.py", line 1560, in execute_sql
    cursor = self.connection.cursor()
  File "/home/apollo/.local/lib/python3.10/site-packages/django/utils/asyncio.py", line 26, in inner
    return func(*args, **kwargs)
  File "/home/apollo/.local/lib/python3.10/site-packages/django/db/backends/base/base.py", line 316, in cursor
    return self._cursor()
  File "/home/apollo/.local/lib/python3.10/site-packages/django/db/backends/base/base.py", line 292, in _cursor
    self.ensure_connection()
  File "/home/apollo/.local/lib/python3.10/site-packages/django/utils/asyncio.py", line 26, in inner
    return func(*args, **kwargs)
  File "/home/apollo/.local/lib/python3.10/site-packages/django/db/backends/base/base.py", line 274, in ensure_connection
    with self.wrap_database_errors:
  File "/home/apollo/.local/lib/python3.10/site-packages/django/db/utils.py", line 91, in __exit__
    raise dj_exc_value.with_traceback(traceback) from exc_value
  File "/home/apollo/.local/lib/python3.10/site-packages/django/db/backends/base/base.py", line 275, in ensure_connection
    self.connect()
  File "/home/apollo/.local/lib/python3.10/site-packages/django/utils/asyncio.py", line 26, in inner
    return func(*args, **kwargs)
  File "/home/apollo/.local/lib/python3.10/site-packages/django/db/backends/base/base.py", line 256, in connect
    self.connection = self.get_new_connection(conn_params)
  File "/home/apollo/.local/lib/python3.10/site-packages/django/utils/asyncio.py", line 26, in inner
    return func(*args, **kwargs)
  File "/home/apollo/.local/lib/python3.10/site-packages/django/db/backends/postgresql/base.py", line 277, in get_new_connection
    connection = self.Database.connect(**conn_params)
  File "/home/apollo/.local/lib/python3.10/site-packages/psycopg2/__init__.py", line 122, in connect
    conn = _connect(dsn, connection_factory=connection_factory, **kwasync)
django.db.utils.OperationalError: connection to server on socket "/var/run/postgresql/.s.PGSQL.5432" failed: No such file or directory
	Is the server running locally and accepting connections on that socket?

"GET /api/asset/get/2 HTTP/1.1" 500 59
